Workbook

Sheet Hoja1
A1: estado | B1: mes | C1: año | D1: rateper100000people | E1: unemployment rate | F1: population | G1: ind | H1: GDP | I1: rgdp | J1: rgdpgrowth | K1: poverty
A2: Alabama | B2: 1 | C2: 2021 | D2: 12.2 | E2: 4.2 | F2: 5050380 | G2: =+A2&C2 -> Alabama2021 | H2: =+INDEX(Sheet1!C:C, MATCH(Hoja1!G2, Sheet1!D:D, 0)) -> 260018.4 | I2: =+INDEX(Sheet1!G:G, MATCH(Hoja1!G2, Sheet1!I:I, 0)) -> 107899 | J2: =+INDEX(Sheet1!H:H, MATCH(Hoja1!G2, Sheet1!I:I, 0)) -> 0.05145246 | K2: =+INDEX(Sheet1!L:L, MATCH(Hoja1!G2,Sheet1!M:M, 0)) -> 15.9
A3: Alabama | B3: 2 | C3: 2021 | D3: 11.5 | E3: 3.9 | F3: 5050380 | G3: =+A3&C3 -> Alabama2021 | H3: =+INDEX(Sheet1!C:C, MATCH(Hoja1!G3, Sheet1!D:D, 0)) -> 260018.4 | I3: =+INDEX(Sheet1!G:G, MATCH(Hoja1!G3, Sheet1!I:I, 0)) -> 107899 | J3: =+INDEX(Sheet1!H:H, MATCH(Hoja1!G3, Sheet1!I:I, 0)) -> 0.05145246 | K3: =+INDEX(Sheet1!L:L, MATCH(Hoja1!G3,Sheet1!M:M, 0)) -> 15.9
A4: Alabama | B4: 3 | C4: 2021 | D4: 12.08 | E4: 3.8 | F4: 5050380 | G4: =+A4&C4 -> Alabama2021 | H4: =+INDEX(Sheet1!C:C, MATCH(Hoja1!G4, Sheet1!D:D, 0)) -> 260018.4 | I4: =+INDEX(Sheet1!G:G, MATCH(Hoja1!G4, Sheet1!I:I, 0)) -> 107899 | J4: =+INDEX(Sheet1!H:H, MATCH(Hoja1!G4, Sheet1!I:I, 0)) -> 0.05145246 | K4: =+INDEX(Sheet1!L:L, MATCH(Hoja1!G4,Sheet1!M:M, 0)) -> 15.9
A5: Alabama | B5: 4 | C5: 2021 | D5: 10.94 | E5: 3.7 | F5: 5050380 | G5: =+A5&C5 -> Alabama2021 | H5: =+INDEX(Sheet1!C:C, MATCH(Hoja1!G5, Sheet1!D:D, 0)) -> 260018.4 | I5: =+INDEX(Sheet1!G:G, MATCH(Hoja1!G5, Sheet1!I:I, 0)) -> 107899 | J5: =+INDEX(Sheet1!H:H, MATCH(Hoja1!G5, Sheet1!I:I, 0)) -> 0.05145246 | K5: =+INDEX(Sheet1!L:L, MATCH(Hoja1!G5,Sheet1!M:M, 0)) -> 15.9
A6: Alabama | B6: 5 | C6: 2021 | D6: 12.38 | E6: 3.5 | F6: 5050380 | G6: =+A6&C6 -> Alabama2021 | H6: =+INDEX(Sheet1!C:C, MATCH(Hoja1!G6, Sheet1!D:D, 0)) -> 260018.4 | I6: =+INDEX(Sheet1!G:G, MATCH(Hoja1!G6, Sheet1!I:I, 0)) -> 107899 | J6: =+INDEX(Sheet1!H:H, MATCH(Hoja1!G6, Sheet1!I:I, 0)) -> 0.05145246 | K6: =+INDEX(Sheet1!L:L, MATCH(Hoja1!G6,Sheet1!M:M, 0)) -> 15.9
A7: Alabama | B7: 6 | C7: 2021 | D7: 12.47 | E7: 3.5 | F7: 5050380 | G7: =+A7&C7 -> Alabama2021 | H7: =+INDEX(Sheet1!C:C, MATCH(Hoja1!G7, Sheet1!D:D, 0)) -> 260018.4 | I7: =+INDEX(Sheet1!G:G, MATCH(Hoja1!G7, Sheet1!I:I, 0)) -> 107899 | J7: =+INDEX(Sheet1!H:H, MATCH(Hoja1!G7, Sheet1!I:I, 0)) -> 0.05145246 | K7: =+INDEX(Sheet1!L:L, MATCH(Hoja1!G7,Sheet1!M:M, 0)) -> 15.9
A8: Alabama | B8: 7 | C8: 2021 | D8: 16.4 | E8: 3.3 | F8: 5050380 | G8: =+A8&C8 -> Alabama2021 | H8: =+INDEX(Sheet1!C:C, MATCH(Hoja1!G8, Sheet1!D:D, 0)) -> 260018.4 | I8: =+INDEX(Sheet1!G:G, MATCH(Hoja1!G8, Sheet1!I:I, 0)) -> 107899 | J8: =+INDEX(Sheet1!H:H, MATCH(Hoja1!G8, Sheet1!I:I, 0)) -> 0.05145246 | K8: =+INDEX(Sheet1!L:L, MATCH(Hoja1!G8,Sheet1!M:M, 0)) -> 15.9
A9: Alabama | B9: 8 | C9: 2021 | D9: 14.87 | E9: 3.2 | F9: 5050380 | G9: =+A9&C9 -> Alabama2021 | H9: =+INDEX(Sheet1!C:C, MATCH(Hoja1!G9, Sheet1!D:D, 0)) -> 260018.4 | I9: =+INDEX(Sheet1!G:G, MATCH(Hoja1!G9, Sheet1!I:I, 0)) -> 107899 | J9: =+INDEX(Sheet1!H:H, MATCH(Hoja1!G9, Sheet1!I:I, 0)) -> 0.05145246 | K9: =+INDEX(Sheet1!L:L, MATCH(Hoja1!G9,Sheet1!M:M, 0)) -> 15.9
A10: Alabama | B10: 9 | C10: 2021 | D10: 15.28 | E10: 3 | F10: 5050380 | G10: =+A10&C10 -> Alabama2021 | H10: =+INDEX(Sheet1!C:C, MATCH(Hoja1!G10, Sheet1!D:D, 0)) -> 260018.4 | I10: =+INDEX(Sheet1!G:G, MATCH(Hoja1!G10, Sheet1!I:I, 0)) -> 107899 | J10: =+INDEX(Sheet1!H:H, MATCH(Hoja1!G10, Sheet1!I:I, 0)) -> 0.05145246 | K10: =+INDEX(Sheet1!L:L, MATCH(Hoja1!G10,Sheet1!M:M, 0)) -> 15.9
A11: Alabama | B11: 10 | C11: 2021 | D11: 17.98 | E11: 2.9 | F11: 5050380 | G11: =+A11&C11 -> Alabama2021 | H11: =+INDEX(Sheet1!C:C, MATCH(Hoja1!G11, Sheet1!D:D, 0)) -> 260018.4 | I11: =+INDEX(Sheet1!G:G, MATCH(Hoja1!G11, Sheet1!I:I, 0)) -> 107899 | J11: =+INDEX(Sheet1!H:H, MATCH(Hoja1!G11, Sheet1!I:I, 0)) -> 0.05145246 | K11: =+INDEX(Sheet1!L:L, MATCH(Hoja1!G11,Sheet1!M:M, 0)) -> 15.9
A12: Alabama | B12: 11 | C12: 2021 | D12: 18.05 | E12: 2.8 | F12: 5050380 | G12: =+A12&C12 -> Alabama2021 | H12: =+INDEX(Sheet1!C:C, MATCH(Hoja1!G12, Sheet1!D:D, 0)) -> 260018.4 | I12: =+INDEX(Sheet1!G:G, MATCH(Hoja1!G12, Sheet1!I:I, 0)) -> 107899 | J12: =+INDEX(Sheet1!H:H, MATCH(Hoja1!G12, Sheet1!I:I, 0)) -> 0.05145246 | K12: =+INDEX(Sheet1!L:L, MATCH(Hoja1!G12,Sheet1!M:M, 0)) -> 15.9
A13: Alabama | B13: 12 | C13: 2021 | D13: 20.46 | E13: 2.7 | F13: 5050380 | G13: =+A13&C13 -> Alabama2021 | H13: =+INDEX(Sheet1!C:C, MATCH(Hoja1!G13, Sheet1!D:D, 0)) -> 260018.4 | I13: =+INDEX(Sheet1!G:G, MATCH(Hoja1!G13, Sheet1!I:I, 0)) -> 107899 | J13: =+INDEX(Sheet1!H:H, MATCH(Hoja1!G13, Sheet1!I:I, 0)) -> 0.05145246 | K13: =+INDEX(Sheet1!L:L, MATCH(Hoja1!G13,Sheet1!M:M, 0)) -> 15.9
... A148: California | B148: 3 | C148: 2021 | D148: 9.77 | E148: 8.4 | F148: 39145060 | G148: =+A148&C148 -> California2021 | H148: =+INDEX(Sheet1!C:C, MATCH(Hoja1!G148, Sheet1!D:D, 0)) -> 3423958.3 | I148: =+INDEX(Sheet1!G:G, MATCH(Hoja1!G148, Sheet1!I:I, 0)) -> 115093 | J148: =+INDEX(Sheet1!H:H, MATCH(Hoja1!G148, Sheet1!I:I, 0)) -> 0.075293832 | K148: =+INDEX(Sheet1!L:L, MATCH(Hoja1!G148,Sheet1!M:M, 0)) -> 11.9
A149: California | B149: 4 | C149: 2021 | D149: 10 | E149: 8.3 | F149: 39145060 | G149: =+A149&C149 -> California2021 | H149: =+INDEX(Sheet1!C:C, MATCH(Hoja1!G149, Sheet1!D:D, 0)) -> 3423958.3 | I149: =+INDEX(Sheet1!G:G, MATCH(Hoja1!G149, Sheet1!I:I, 0)) -> 115093 | J149: =+INDEX(Sheet1!H:H, MATCH(Hoja1!G149, Sheet1!I:I, 0)) -> 0.075293832 | K149: =+INDEX(Sheet1!L:L, MATCH(Hoja1!G149,Sheet1!M:M, 0)) -> 11.9
A150: California | B150: 5 | C150: 2021 | D150: 12.52 | E150: 7.9 | F150: 39145060 | G150: =+A150&C150 -> California2021 | H150: =+INDEX(Sheet1!C:C, MATCH(Hoja1!G150, Sheet1!D:D, 0)) -> 3423958.3 | I150: =+INDEX(Sheet1!G:G, MATCH(Hoja1!G150, Sheet1!I:I, 0)) -> 115093 | J150: =+INDEX(Sheet1!H:H, MATCH(Hoja1!G150, Sheet1!I:I, 0)) -> 0.075293832 | K150: =+INDEX(Sheet1!L:L, MATCH(Hoja1!G150,Sheet1!M:M, 0)) -> 11.9
A151: California | B151: 6 | C151: 2021 | D151: 11.86 | E151: 7.8 | F151: 39145060 | G151: =+A151&C151 -> California2021 | H151: =+INDEX(Sheet1!C:C, MATCH(Hoja1!G151, Sheet1!D:D, 0)) -> 3423958.3 | I151: =+INDEX(Sheet1!G:G, MATCH(Hoja1!G151, Sheet1!I:I, 0)) -> 115093 | J151: =+INDEX(Sheet1!H:H, MATCH(Hoja1!G151, Sheet1!I:I, 0)) -> 0.075293832 | K151: =+INDEX(Sheet1!L:L, MATCH(Hoja1!G151,Sheet1!M:M, 0)) -> 11.9
A152: California | B152: 7 | C152: 2021 | D152: 13.37 | E152: 7.4 | F152: 39145060 | G152: =+A152&C152 -> California2021 | H152: =+INDEX(Sheet1!C:C, MATCH(Hoja1!G152, Sheet1!D:D, 0)) -> 3423958.3 | I152: =+INDEX(Sheet1!G:G, MATCH(Hoja1!G152, Sheet1!I:I, 0)) -> 115093 | J152: =+INDEX(Sheet1!H:H, MATCH(Hoja1!G152, Sheet1!I:I, 0)) -> 0.075293832 | K152: =+INDEX(Sheet1!L:L, MATCH(Hoja1!G152,Sheet1!M:M, 0)) -> 11.9
A153: California | B153: 8 | C153: 2021 | D153: 12.46 | E153: 7 | F153: 39145060 | G153: =+A153&C153 -> California2021 | H153: =+INDEX(Sheet1!C:C, MATCH(Hoja1!G153, Sheet1!D:D, 0)) -> 3423958.3 | I153: =+INDEX(Sheet1!G:G, MATCH(Hoja1!G153, Sheet1!I:I, 0)) -> 115093 | J153: =+INDEX(Sheet1!H:H, MATCH(Hoja1!G153, Sheet1!I:I, 0)) -> 0.075293832 | K153: =+INDEX(Sheet1!L:L, MATCH(Hoja1!G153,Sheet1!M:M, 0)) -> 11.9
A154: California | B154: 9 | C154: 2021 | D154: 12.67 | E154: 6.5 | F154: 39145060 | G154: =+A154&C154 -> California2021 | H154: =+INDEX(Sheet1!C:C, MATCH(Hoja1!G154, Sheet1!D:D, 0)) -> 3423958.3 | I154: =+INDEX(Sheet1!G:G, MATCH(Hoja1!G154, Sheet1!I:I, 0)) -> 115093 | J154: =+INDEX(Sheet1!H:H, MATCH(Hoja1!G154, Sheet1!I:I, 0)) -> 0.075293832 | K154: =+INDEX(Sheet1!L:L, MATCH(Hoja1!G154,Sheet1!M:M, 0)) -> 11.9
A155: California | B155: 10 | C155: 2021 | D155: 12.91 | E155: 6.1 | F155: 39145060 | G155: =+A155&C155 -> California2021 | H155: =+INDEX(Sheet1!C:C, MATCH(Hoja1!G155, Sheet1!D:D, 0)) -> 3423958.3 | I155: =+INDEX(Sheet1!G:G, MATCH(Hoja1!G155, Sheet1!I:I, 0)) -> 115093 | J155: =+INDEX(Sheet1!H:H, MATCH(Hoja1!G155, Sheet1!I:I, 0)) -> 0.075293832 | K155: =+INDEX(Sheet1!L:L, MATCH(Hoja1!G155,Sheet1!M:M, 0)) -> 11.9
A156: California | B156: 11 | C156: 2021 | D156: 15.37 | E156: 5.7 | F156: 39145060 | G156: =+A156&C156 -> California2021 | H156: =+INDEX(Sheet1!C:C, MATCH(Hoja1!G156, Sheet1!D:D, 0)) -> 3423958.3 | I156: =+INDEX(Sheet1!G:G, MATCH(Hoja1!G156, Sheet1!I:I, 0)) -> 115093 | J156: =+INDEX(Sheet1!H:H, MATCH(Hoja1!G156, Sheet1!I:I, 0)) -> 0.075293832 | K156: =+INDEX(Sheet1!L:L, MATCH(Hoja1!G156,Sheet1!M:M, 0)) -> 11.9
A157: California | B157: 12 | C157: 2021 | D157: 16.3 | E157: 5.5 | F157: 39145060 | G157: =+A157&C157 -> California2021 | H157: =+INDEX(Sheet1!C:C, MATCH(Hoja1!G157, Sheet1!D:D, 0)) -> 3423958.3 | I157: =+INDEX(Sheet1!G:G, MATCH(Hoja1!G157, Sheet1!I:I, 0)) -> 115093 | J157: =+INDEX(Sheet1!H:H, MATCH(Hoja1!G157, Sheet1!I:I, 0)) -> 0.075293832 | K157: =+INDEX(Sheet1!L:L, MATCH(Hoja1!G157,Sheet1!M:M, 0)) -> 11.9
A158: California | B158: 1 | C158: 2022 | D158: 16.97 | E158: 5.2 | F158: 39040616 | G158: =+A158&C158 -> California2022 | H158: =+INDEX(Sheet1!C:C, MATCH(Hoja1!G158, Sheet1!D:D, 0)) -> 3660415.7 | I158: =+INDEX(Sheet1!G:G, MATCH(Hoja1!G158, Sheet1!I:I, 0)) -> 116181 | J158: =+INDEX(Sheet1!H:H, MATCH(Hoja1!G158, Sheet1!I:I, 0)) -> 0.0094532248 | K158: =+INDEX(Sheet1!L:L, MATCH(Hoja1!G158,Sheet1!M:M, 0)) -> 11.2
A159: California | B159: 2 | C159: 2022 | D159: 17.81 | E159: 4.8 | F159: 39040616 | G159: =+A159&C159 -> California2022 | H159: =+INDEX(Sheet1!C:C, MATCH(Hoja1!G159, Sheet1!D:D, 0)) -> 3660415.7 | I159: =+INDEX(Sheet1!G:G, MATCH(Hoja1!G159, Sheet1!I:I, 0)) -> 116181 | J159: =+INDEX(Sheet1!H:H, MATCH(Hoja1!G159, Sheet1!I:I, 0)) -> 0.0094532248 | K159: =+INDEX(Sheet1!L:L, MATCH(Hoja1!G159,Sheet1!M:M, 0)) -> 11.2
A160: California | B160: 3 | C160: 2022 | D160: 18.97 | E160: 4.4 | F160: 39040616 | G160: =+A160&C160 -> California2022 | H160: =+INDEX(Sheet1!C:C, MATCH(Hoja1!G160, Sheet1!D:D, 0)) -> 3660415.7 | I160: =+INDEX(Sheet1!G:G, MATCH(Hoja1!G160, Sheet1!I:I, 0)) -> 116181 | J160: =+INDEX(Sheet1!H:H, MATCH(Hoja1!G160, Sheet1!I:I, 0)) -> 0.0094532248 | K160: =+INDEX(Sheet1!L:L, MATCH(Hoja1!G160,Sheet1!M:M, 0)) -> 11.2
A161: California | B161: 4 | C161: 2022 | D161: 18.13 | E161: 4.2 | F161: 39040616 | G161: =+A161&C161 -> California2022 | H161: =+INDEX(Sheet1!C:C, MATCH(Hoja1!G161, Sheet1!D:D, 0)) -> 3660415.7 | I161: =+INDEX(Sheet1!G:G, MATCH(Hoja1!G161, Sheet1!I:I, 0)) -> 116181 | J161: =+INDEX(Sheet1!H:H, MATCH(Hoja1!G161, Sheet1!I:I, 0)) -> 0.0094532248 | K161: =+INDEX(Sheet1!L:L, MATCH(Hoja1!G161,Sheet1!M:M, 0)) -> 11.2
... A213: Colorado | B213: 8 | C213: 2023 | D213: 31.77 | E213: 3.2 | F213: 5877610 | G213: =+A213&C213 -> Colorado2023 | H213: =+INDEX(Sheet1!C:C, MATCH(Hoja1!G213, Sheet1!D:D, 0)) -> 529626.5 | I213: =+INDEX(Sheet1!G:G, MATCH(Hoja1!G213, Sheet1!I:I, 0)) -> 124799 | J213: =+INDEX(Sheet1!H:H, MATCH(Hoja1!G213, Sheet1!I:I, 0)) -> 0.043548428 | K213: =+INDEX(Sheet1!L:L, MATCH(Hoja1!G213,Sheet1!M:M, 0)) -> 8.5
A214: Colorado | B214: 9 | C214: 2023 | D214: 29 | E214: 3.3 | F214: 5877610 | G214: =+A214&C214 -> Colorado2023 | H214: =+INDEX(Sheet1!C:C, MATCH(Hoja1!G214, Sheet1!D:D, 0)) -> 529626.5 | I214: =+INDEX(Sheet1!G:G, MATCH(Hoja1!G214, Sheet1!I:I, 0)) -> 124799 | J214: =+INDEX(Sheet1!H:H, MATCH(Hoja1!G214, Sheet1!I:I, 0)) -> 0.043548428 | K214: =+INDEX(Sheet1!L:L, MATCH(Hoja1!G214,Sheet1!M:M, 0)) -> 8.5
A215: Colorado | B215: 10 | C215: 2023 | D215: 32.22 | E215: 3.3 | F215: 5877610 | G215: =+A215&C215 -> Colorado2023 | H215: =+INDEX(Sheet1!C:C, MATCH(Hoja1!G215, Sheet1!D:D, 0)) -> 529626.5 | I215: =+INDEX(Sheet1!G:G, MATCH(Hoja1!G215, Sheet1!I:I, 0)) -> 124799 | J215: =+INDEX(Sheet1!H:H, MATCH(Hoja1!G215, Sheet1!I:I, 0)) -> 0.043548428 | K215: =+INDEX(Sheet1!L:L, MATCH(Hoja1!G215,Sheet1!M:M, 0)) -> 8.5
A216: Colorado | B216: 11 | C216: 2023 | D216: 34.35 | E216: 3.3 | F216: 5877610 | G216: =+A216&C216 -> Colorado2023 | H216: =+INDEX(Sheet1!C:C, MATCH(Hoja1!G216, Sheet1!D:D, 0)) -> 529626.5 | I216: =+INDEX(Sheet1!G:G, MATCH(Hoja1!G216, Sheet1!I:I, 0)) -> 124799 | J216: =+INDEX(Sheet1!H:H, MATCH(Hoja1!G216, Sheet1!I:I, 0)) -> 0.043548428 | K216: =+INDEX(Sheet1!L:L, MATCH(Hoja1!G216,Sheet1!M:M, 0)) -> 8.5
A217: Colorado | B217: 12 | C217: 2023 | D217: 37.79 | E217: 3.3 | F217: 5877610 | G217: =+A217&C217 -> Colorado2023 | H217: =+INDEX(Sheet1!C:C, MATCH(Hoja1!G217, Sheet1!D:D, 0)) -> 529626.5 | I217: =+INDEX(Sheet1!G:G, MATCH(Hoja1!G217, Sheet1!I:I, 0)) -> 124799 | J217: =+INDEX(Sheet1!H:H, MATCH(Hoja1!G217, Sheet1!I:I, 0)) -> 0.043548428 | K217: =+INDEX(Sheet1!L:L, MATCH(Hoja1!G217,Sheet1!M:M, 0)) -> 8.5
A218: Connecticut | B218: 1 | C218: 2021 | D218: 24.38 | E218: 7.1 | F218: 3603691 | G218: =+A218&C218 -> Connecticut2021 | H218: =+INDEX(Sheet1!C:C, MATCH(Hoja1!G218, Sheet1!D:D, 0)) -> 296801.3 | I218: =+INDEX(Sheet1!G:G, MATCH(Hoja1!G218, Sheet1!I:I, 0)) -> 98526 | J218: =+INDEX(Sheet1!H:H, MATCH(Hoja1!G218, Sheet1!I:I, 0)) -> 0.034795669 | K218: =+INDEX(Sheet1!L:L, MATCH(Hoja1!G218,Sheet1!M:M, 0)) -> 8
A219: Connecticut | B219: 2 | C219: 2021 | D219: 23.05 | E219: 7.1 | F219: 3603691 | G219: =+A219&C219 -> Connecticut2021 | H219: =+INDEX(Sheet1!C:C, MATCH(Hoja1!G219, Sheet1!D:D, 0)) -> 296801.3 | I219: =+INDEX(Sheet1!G:G, MATCH(Hoja1!G219, Sheet1!I:I, 0)) -> 98526 | J219: =+INDEX(Sheet1!H:H, MATCH(Hoja1!G219, Sheet1!I:I, 0)) -> 0.034795669 | K219: =+INDEX(Sheet1!L:L, MATCH(Hoja1!G219,Sheet1!M:M, 0)) -> 8
A220: Connecticut | B220: 3 | C220: 2021 | D220: 23.8 | E220: 7 | F220: 3603691 | G220: =+A220&C220 -> Connecticut2021 | H220: =+INDEX(Sheet1!C:C, MATCH(Hoja1!G220, Sheet1!D:D, 0)) -> 296801.3 | I220: =+INDEX(Sheet1!G:G, MATCH(Hoja1!G220, Sheet1!I:I, 0)) -> 98526 | J220: =+INDEX(Sheet1!H:H, MATCH(Hoja1!G220, Sheet1!I:I, 0)) -> 0.034795669 | K220: =+INDEX(Sheet1!L:L, MATCH(Hoja1!G220,Sheet1!M:M, 0)) -> 8
A221: Connecticut | B221: 4 | C221: 2021 | D221: 21.02 | E221: 7.1 | F221: 3603691 | G221: =+A221&C221 -> Connecticut2021 | H221: =+INDEX(Sheet1!C:C, MATCH(Hoja1!G221, Sheet1!D:D, 0)) -> 296801.3 | I221: =+INDEX(Sheet1!G:G, MATCH(Hoja1!G221, Sheet1!I:I, 0)) -> 98526 | J221: =+INDEX(Sheet1!H:H, MATCH(Hoja1!G221, Sheet1!I:I, 0)) -> 0.034795669 | K221: =+INDEX(Sheet1!L:L, MATCH(Hoja1!G221,Sheet1!M:M, 0)) -> 8
A222: Connecticut | B222: 5 | C222: 2021 | D222: 22.99 | E222: 6.9 | F222: 3603691 | G222: =+A222&C222 -> Connecticut2021 | H222: =+INDEX(Sheet1!C:C, MATCH(Hoja1!G222, Sheet1!D:D, 0)) -> 296801.3 | I222: =+INDEX(Sheet1!G:G, MATCH(Hoja1!G222, Sheet1!I:I, 0)) -> 98526 | J222: =+INDEX(Sheet1!H:H, MATCH(Hoja1!G222, Sheet1!I:I, 0)) -> 0.034795669 | K222: =+INDEX(Sheet1!L:L, MATCH(Hoja1!G222,Sheet1!M:M, 0)) -> 8
A223: Connecticut | B223: 6 | C223: 2021 | D223: 25.27 | E223: 6.8 | F223: 3603691 | G223: =+A223&C223 -> Connecticut2021 | H223: =+INDEX(Sheet1!C:C, MATCH(Hoja1!G223, Sheet1!D:D, 0)) -> 296801.3 | I223: =+INDEX(Sheet1!G:G, MATCH(Hoja1!G223, Sheet1!I:I, 0)) -> 98526 | J223: =+INDEX(Sheet1!H:H, MATCH(Hoja1!G223, Sheet1!I:I, 0)) -> 0.034795669 | K223: =+INDEX(Sheet1!L:L, MATCH(Hoja1!G223,Sheet1!M:M, 0)) -> 8
A224: Connecticut | B224: 7 | C224: 2021 | D224: 25.13 | E224: 6.5 | F224: 3603691 | G224: =+A224&C224 -> Connecticut2021 | H224: =+INDEX(Sheet1!C:C, MATCH(Hoja1!G224, Sheet1!D:D, 0)) -> 296801.3 | I224: =+INDEX(Sheet1!G:G, MATCH(Hoja1!G224, Sheet1!I:I, 0)) -> 98526 | J224: =+INDEX(Sheet1!H:H, MATCH(Hoja1!G224, Sheet1!I:I, 0)) -> 0.034795669 | K224: =+INDEX(Sheet1!L:L, MATCH(Hoja1!G224,Sheet1!M:M, 0)) -> 8
A225: Connecticut | B225: 8 | C225: 2021 | D225: 23.82 | E225: 6.2 | F225: 3603691 | G225: =+A225&C225 -> Connecticut2021 | H225: =+INDEX(Sheet1!C:C, MATCH(Hoja1!G225, Sheet1!D:D, 0)) -> 296801.3 | I225: =+INDEX(Sheet1!G:G, MATCH(Hoja1!G225, Sheet1!I:I, 0)) -> 98526 | J225: =+INDEX(Sheet1!H:H, MATCH(Hoja1!G225, Sheet1!I:I, 0)) -> 0.034795669 | K225: =+INDEX(Sheet1!L:L, MATCH(Hoja1!G225,Sheet1!M:M, 0)) -> 8
...

Sheet Sheet1
A1: GeoName | B1: Values | C1: GDP | D1: Ind | E1: GeoName | F1: Values | G1: rgdp | H1: rgdpgrowth | I1: ind2 | J1: State | K1: Values | L1: poverty | M1: ind3
A2: Alabama | B2: 2023 | C2: 304935.6 | D2: =+A2&B2 -> Alabama2023 | E2: Alabama | F2: 2021 | G2: 107899 | H2: 0.05145246 | I2: =+E2&F2 -> Alabama2021 | J2: Alabama | K2: 2021 | L2: 15.9 | M2: =+J2&K2 -> Alabama2021
A3: =+A2 -> Alabama | B3: 2022 | C3: 284949.1 | D3: =+A3&B3 -> Alabama2022 | E3: Alabama | F3: 2022 | G3: 110129 | H3: 0.020667476 | I3: =+E3&F3 -> Alabama2022 | J3: Alabama | K3: 2022 | L3: 13.6 | M3: =+J3&K3 -> Alabama2022
A4: =+A3 -> Alabama | B4: 2021 | C4: 260018.4 | D4: =+A4&B4 -> Alabama2021 | E4: Alabama | F4: 2023 | G4: 113267 | H4: 0.028493857 | I4: =+E4&F4 -> Alabama2023 | J4: Alabama | K4: 2023 | L4: 14.2 | M4: =+J4&K4 -> Alabama2023
A5: Alaska | B5: 2023 | C5: 68056 | D5: =+A5&B5 -> Alaska2023 | E5: Alaska | F5: 2021 | G5: 96085 | H5: 0.022278729 | I5: =+E5&F5 -> Alaska2021 | J5: Alaska | K5: 2021 | L5: 11.4 | M5: =+J5&K5 -> Alaska2021
A6: =+A5 -> Alaska | B6: 2022 | C6: 66271.9 | D6: =+A6&B6 -> Alaska2022 | E6: Alaska | F6: 2022 | G6: 94802 | H6: -0.013352761 | I6: =+E6&F6 -> Alaska2022 | J6: Alaska | K6: 2022 | L6: 9.6 | M6: =+J6&K6 -> Alaska2022
A7: =+A6 -> Alaska | B7: 2021 | C7: 58943.5 | D7: =+A7&B7 -> Alaska2021 | E7: Alaska | F7: 2023 | G7: 100950 | H7: 0.064850953 | I7: =+E7&F7 -> Alaska2023 | J7: Alaska | K7: 2023 | L7: 10.1 | M7: =+J7&K7 -> Alaska2023
A8: Arizona | B8: 2023 | C8: 522767.2 | D8: =+A8&B8 -> Arizona2023 | E8: Arizona | F8: 2021 | G8: 118594 | H8: 0.082210156 | I8: =+E8&F8 -> Arizona2021 | J8: Arizona | K8: 2021 | L8: 12.6 | M8: =+J8&K8 -> Arizona2021
A9: =+A8 -> Arizona | B9: 2022 | C9: 484052.2 | D9: =+A9&B9 -> Arizona2022 | E9: Arizona | F9: 2022 | G9: 123155 | H9: 0.038458944 | I9: =+E9&F9 -> Arizona2022 | J9: Arizona | K9: 2022 | L9: 12.7 | M9: =+J9&K9 -> Arizona2022
A10: =+A9 -> Arizona | B10: 2021 | C10: 436778.6 | D10: =+A10&B10 -> Arizona2021 | E10: Arizona | F10: 2023 | G10: 126809 | H10: 0.029669928 | I10: =+E10&F10 -> Arizona2023 | J10: Arizona | K10: 2023 | L10: 11.9 | M10: =+J10&K10 -> Arizona2023
A11: Arkansas | B11: 2023 | C11: 178606.4 | D11: =+A11&B11 -> Arkansas2023 | E11: Arkansas | F11: 2021 | G11: 110963 | H11: 0.071081767 | I11: =+E11&F11 -> Arkansas2021 | J11: Arkansas | K11: 2021 | L11: 16.8 | M11: =+J11&K11 -> Arkansas2021
A12: =+A11 -> Arkansas | B12: 2022 | C12: 168605.8 | D12: =+A12&B12 -> Arkansas2022 | E12: Arkansas | F12: 2022 | G12: 112656 | H12: 0.015257338 | I12: =+E12&F12 -> Arkansas2022 | J12: Arkansas | K12: 2022 | L12: 16.6 | M12: =+J12&K12 -> Arkansas2022
A13: =+A12 -> Arkansas | B13: 2021 | C13: 154052.5 | D13: =+A13&B13 -> Arkansas2021 | E13: Arkansas | F13: 2023 | G13: 115319 | H13: 0.023638333 | I13: =+E13&F13 -> Arkansas2023 | J13: Arkansas | K13: 2023 | L13: 13.8 | M13: =+J13&K13 -> Arkansas2023
A14: California | B14: 2023 | C14: 3870378.9 | D14: =+A14&B14 -> California2023 | E14: California | F14: 2021 | G14: 115093 | H14: 0.075293832 | I14: =+E14&F14 -> California2021 | J14: California | K14: 2021 | L14: 11.9 | M14: =+J14&K14 -> California2021
A15: =+A14 -> California | B15: 2022 | C15: 3660415.7 | D15: =+A15&B15 -> California2022 | E15: California | F15: 2022 | G15: 116181 | H15: 0.0094532248 | I15: =+E15&F15 -> California2022 | J15: California | K15: 2022 | L15: 11.2 | M15: =+J15&K15 -> California2022
A16: =+A15 -> California | B16: 2021 | C16: 3423958.3 | D16: =+A16&B16 -> California2021 | E16: California | F16: 2023 | G16: 118540 | H16: 0.020304525 | I16: =+E16&F16 -> California2023 | J16: California | K16: 2023 | L16: 11.9 | M16: =+J16&K16 -> California2023
A17: Colorado | B17: 2023 | C17: 529626.5 | D17: =+A17&B17 -> Colorado2023 | E17: Colorado | F17: 2021 | G17: 116060 | H17: 0.069076372 | I17: =+E17&F17 -> Colorado2021 | J17: Colorado | K17: 2021 | L17: 7.9 | M17: =+J17&K17 -> Colorado2021
A18: =+A17 -> Colorado | B18: 2022 | C18: 494672.8 | D18: =+A18&B18 -> Colorado2022 | E18: Colorado | F18: 2022 | G18: 119591 | H18: 0.030423919 | I18: =+E18&F18 -> Colorado2022 | J18: Colorado | K18: 2022 | L18: 8.1 | M18: =+J18&K18 -> Colorado2022
A19: =+A18 -> Colorado | B19: 2021 | C19: 445835.7 | D19: =+A19&B19 -> Colorado2021 | E19: Colorado | F19: 2023 | G19: 124799 | H19: 0.043548428 | I19: =+E19&F19 -> Colorado2023 | J19: Colorado | K19: 2023 | L19: 8.5 | M19: =+J19&K19 -> Colorado2023
A20: Connecticut | B20: 2023 | C20: 345911.9 | D20: =+A20&B20 -> Connecticut2023 | E20: Connecticut | F20: 2021 | G20: 98526 | H20: 0.034795669 | I20: =+E20&F20 -> Connecticut2021 | J20: Connecticut | K20: 2021 | L20: 8 | M20: =+J20&K20 -> Connecticut2021
A21: =+A20 -> Connecticut | B21: 2022 | C21: 321686.4 | D21: =+A21&B21 -> Connecticut2022 | E21: Connecticut | F21: 2022 | G21: 101862 | H21: 0.033859083 | I21: =+E21&F21 -> Connecticut2022 | J21: Connecticut | K21: 2022 | L21: 10.2 | M21: =+J21&K21 -> Connecticut2022
A22: =+A21 -> Connecticut | B22: 2021 | C22: 296801.3 | D22: =+A22&B22 -> Connecticut2021 | E22: Connecticut | F22: 2023 | G22: 104657 | H22: 0.027439084 | I22: =+E22&F22 -> Connecticut2023 | J22: Connecticut | K22: 2023 | L22: 8.3 | M22: =+J22&K22 -> Connecticut2023
A23: Delaware | B23: 2023 | C23: 98068.7 | D23: =+A23&B23 -> Delaware2023 | E23: Delaware | F23: 2021 | G23: 107334 | H23: 0.029651871 | I23: =+E23&F23 -> Delaware2021 | J23: Delaware | K23: 2021 | L23: 11.7 | M23: =+J23&K23 -> Delaware2021
A24: =+A23 -> Delaware | B24: 2022 | C24: 92558.2 | D24: =+A24&B24 -> Delaware2022 | E24: Delaware | F24: 2022 | G24: 110917 | H24: 0.03338178 | I24: =+E24&F24 -> Delaware2022 | J24: Delaware | K24: 2022 | L24: 9.3 | M24: =+J24&K24 -> Delaware2022
A25: =+A24 -> Delaware | B25: 2021 | C25: 83069.8 | D25: =+A25&B25 -> Delaware2021 | E25: Delaware | F25: 2023 | G25: 112161 | H25: 0.011215594 | I25: =+E25&F25 -> Delaware2023 | J25: Delaware | K25: 2023 | L25: 7.8 | M25: =+J25&K25 -> Delaware2023
A26: District of Columbia | B26: 2023 | C26: 176501.7 | D26: =+A26&B26 -> District of Columbia2023 | E26: District of Columbia | F26: 2021 | G26: 106584 | H26: 0.039955507 | I26: =+E26&F26 -> District of Columbia2021 | J26: District of Columbia | K26: 2021 | L26: 14 | M26: =+J26&K26 -> District of Columbia2021
A27: =+A26 -> District of Columbia | B27: 2022 | C27: 165768.4 | D27: =+A27&B27 -> District of Columbia2022 | E27: District of Columbia | F27: 2022 | G27: 107637 | H27: 0.0098795316 | I27: =+E27&F27 -> District of Columbia2022 | J27: District of Columbia | K27: 2022 | L27: 13.4 | M27: =+J27&K27 -> District of Columbia2022
A28: =+A27 -> District of Columbia | B28: 2021 | C28: 156537.5 | D28: =+A28&B28 -> District of Columbia2021 | E28: District of Columbia | F28: 2023 | G28: 108731 | H28: 0.010163791 | I28: =+E28&F28 -> District of Columbia2023 | J28: District of Columbia | K28: 2023 | L28: 12.7 | M28: =+J28&K28 -> District of Columbia2023
A29: Far West | B29: 2023 | C29: 5421427.9 | D29: =+A29&B29 -> Far West2023 | E29: Far West | F29: 2021 | G29: 114616 | H29: 0.07313328 | I29: =+E29&F29 -> Far West2021 | J29: Florida | K29: 2021 | L29: 12.6 | M29: =+J29&K29 -> Florida2021
A30: =+A29 -> Far West | B30: 2022 | C30: 5098918.7 | D30: =+A30&B30 -> Far West2022 | E30: Far West | F30: 2022 | G30: 116182 | H30: 0.013663014 | I30: =+E30&F30 -> Far West2022 | J30: Florida | K30: 2022 | L30: 13.5 | M30: =+J30&K30 -> Florida2022
A31: =+A30 -> Far West | B31: 2021 | C31: 4741363.3 | D31: =+A31&B31 -> Far West2021 | E31: Far West | F31: 2023 | G31: 119181 | H31: 0.025812949 | I31: =+E31&F31 -> Far West2023 | J31: Florida | K31: 2023 | L31: 11.6 | M31: =+J31&K31 -> Florida2023
A32: Florida | B32: 2023 | C32: 1600810.6 | D32: =+A32&B32 -> Florida2023 | E32: Florida | F32: 2021 | G32: 115338 | H32: 0.094194993 | I32: =+E32&F32 -> Florida2021 | J32: Georgia | K32: 2021 | L32: 14 | M32: =+J32&K32 -> Georgia2021
A33: =+A32 -> Florida | B33: 2022 | C33: 1465281.1 | D33: =+A33&B33 -> Florida2022 | E33: Florida | F33: 2022 | G33: 122172 | H33: 0.059251938 | I33: =+E33&F33 -> Florida2022 | J33: Georgia | K33: 2022 | L33: 11.7 | M33: =+J33&K33 -> Georgia2022
A34: =+A33 -> Florida | B34: 2021 | C34: 1298631.2 | D34: =+A34&B34 -> Florida2021 | E34: Florida | F34: 2023 | G34: 127385 | H34: 0.042669351 | I34: =+E34&F34 -> Florida2023 | J34: Georgia | K34: 2023 | L34: 12.9 | M34: =+J34&K34 -> Georgia2023
A35: Georgia | B35: 2023 | C35: 831827.7 | D35: =+A35&B35 -> Georgia2023 | E35: Georgia | F35: 2021 | G35: 110191 | H35: 0.063281001 | I35: =+E35&F35 -> Georgia2021 | J35: Hawaii | K35: 2021 | L35: 10.9 | M35: =+J35&K35 -> Hawaii2021
A36: =+A35 -> Georgia | B36: 2022 | C36: 779684 | D36: =+A36&B36 -> Georgia2022 | E36: Georgia | F36: 2022 | G36: 114075 | H36: 0.035247888 | I36: =+E36&F36 -> Georgia2022 | J36: Hawaii | K36: 2022 | L36: 8.8 | M36: =+J36&K36 -> Hawaii2022
A37: =+A36 -> Georgia | B37: 2021 | C37: 705546.7 | D37: =+A37&B37 -> Georgia2021 | E37: Georgia | F37: 2023 | G37: 116221 | H37: 0.018812185 | I37: =+E37&F37 -> Georgia2023 | J37: Hawaii | K37: 2023 | L37: 8.2 | M37: =+J37&K37 -> Hawaii2023
A38: Great Lakes | B38: 2023 | C38: 3584948.6 | D38: =+A38&B38 -> Great Lakes2023 | E38: Great Lakes | F38: 2021 | G38: 104823 | H38: 0.056140492 | I38: =+E38&F38 -> Great Lakes2021 | J38: Idaho | K38: 2021 | L38: 9.3 | M38: =+J38&K38 -> Idaho2021
A39: =+A38 -> Great Lakes | B39: 2022 | C39: 3374137.4 | D39: =+A39&B39 -> Great Lakes2022 | E39: Great Lakes | F39: 2022 | G39: 106922 | H39: 0.020024231 | I39: =+E39&F39 -> Great Lakes2022 | J39: Idaho | K39: 2022 | L39: 8.2 | M39: =+J39&K39 -> Idaho2022
A40: =+A39 -> Great Lakes | B40: 2021 | C40: 3080232.8 | D40: =+A40&B40 -> Great Lakes2021 | E40: Great Lakes | F40: 2023 | G40: 108571 | H40: 0.015422457 | I40: =+E40&F40 -> Great Lakes2023 | J40: Idaho | K40: 2023 | L40: 9.1 | M40: =+J40&K40 -> Idaho2023
...
